Workbook

Sheet Summary
A1: FTC Milestone Bonus Tracker — Summary (All Classes)
A5: Class | B5: Site | C5: Tech HC | D5: Projected Total/Employee (PHP) | E5: Projected Class Total (PHP) | F5: Actual T1 Paid (PHP) | G5: Actual T2 Paid (PHP) | H5: Actual T3 Paid (PHP) | I5: Actual Class Total (PHP) | J5: Tranche 1 Date | K5: Tranche 2 Date | L5: Tranche 3 Date | M5: Start Date (NEO) | N5: End Date (Contract End) | O5: Total Stay (Months + Days)
A6: 2026 OGA Contractor Tech 2.2.1 CEB | B6: CEB | C6: ='Tech 2.2.1 CEB'!$K$15 -> 20 | D6: ='Tech 2.2.1 CEB'!$K$13 -> 14583.33 | E6: =C6*D6 -> 291666.6 | F6: ='Tech 2.2.1 CEB'!$G$27 -> 4083.33 | G6: ='Tech 2.2.1 CEB'!$G$51 -> 0 | H6: ='Tech 2.2.1 CEB'!$G$75 -> 0 | I6: =SUM(F6:H6) -> 4083.33 | J6: ='Tech 2.2.1 CEB'!$K$4 -> 46276 | K6: ='Tech 2.2.1 CEB'!$K$5 -> 46306 | L6: ='Tech 2.2.1 CEB'!$K$6 -> 46402 | M6: ='Tech 2.2.1 CEB'!$K$3 -> 46227 | N6: ='Tech 2.2.1 CEB'!$K$6 -> 46402 | O6: =DATEDIF(M6,N6,"m")&" months, "&DATEDIF(M6,N6,"md")&" days" -> 5 months, 22 days
A7: 2026 OGA Contractor Tech 2.2.2 CEB | B7: CEB | C7: ='Tech 2.2.2 CEB'!$K$15 -> 20 | D7: ='Tech 2.2.2 CEB'!$K$13 -> 14583.33 | E7: =C7*D7 -> 291666.6 | F7: ='Tech 2.2.2 CEB'!$G$27 -> 0 | G7: ='Tech 2.2.2 CEB'!$G$51 -> 0 | H7: ='Tech 2.2.2 CEB'!$G$75 -> 0 | I7: =SUM(F7:H7) -> 0 | J7: ='Tech 2.2.2 CEB'!$K$4 -> 46297 | K7: ='Tech 2.2.2 CEB'!$K$5 -> 46328 | L7: ='Tech 2.2.2 CEB'!$K$6 -> 46423 | M7: ='Tech 2.2.2 CEB'!$K$3 -> 46248 | N7: ='Tech 2.2.2 CEB'!$K$6 -> 46423 | O7: =DATEDIF(M7,N7,"m")&" months, "&DATEDIF(M7,N7,"md")&" days" -> 5 months, 22 days
A8: 2026 OGA Contractor Tech 2.2.3 CEB | B8: CEB | C8: ='Tech 2.2.3 CEB'!$K$15 -> 20 | D8: ='Tech 2.2.3 CEB'!$K$13 -> 14583.33 | E8: =C8*D8 -> 291666.6 | F8: ='Tech 2.2.3 CEB'!$G$27 -> 0 | G8: ='Tech 2.2.3 CEB'!$G$51 -> 0 | H8: ='Tech 2.2.3 CEB'!$G$75 -> 0 | I8: =SUM(F8:H8) -> 0 | J8: ='Tech 2.2.3 CEB'!$K$4 -> 46304 | K8: ='Tech 2.2.3 CEB'!$K$5 -> 46335 | L8: ='Tech 2.2.3 CEB'!$K$6 -> 46430 | M8: ='Tech 2.2.3 CEB'!$K$3 -> 46255 | N8: ='Tech 2.2.3 CEB'!$K$6 -> 46430 | O8: =DATEDIF(M8,N8,"m")&" months, "&DATEDIF(M8,N8,"md")&" days" -> 5 months, 22 days
A9: 2026 OGA Contractor Tech 2.2.4 QC | B9: QC | C9: ='Tech 2.2.4 QC'!$K$15 -> 20 | D9: ='Tech 2.2.4 QC'!$K$13 -> 14583.33 | E9: =C9*D9 -> 291666.6 | F9: ='Tech 2.2.4 QC'!$G$27 -> 0 | G9: ='Tech 2.2.4 QC'!$G$51 -> 0 | H9: ='Tech 2.2.4 QC'!$G$75 -> 0 | I9: =SUM(F9:H9) -> 0 | J9: ='Tech 2.2.4 QC'!$K$4 -> 46311 | K9: ='Tech 2.2.4 QC'!$K$5 -> 46342 | L9: ='Tech 2.2.4 QC'!$K$6 -> 46437 | M9: ='Tech 2.2.4 QC'!$K$3 -> 46262 | N9: ='Tech 2.2.4 QC'!$K$6 -> 46437 | O9: =DATEDIF(M9,N9,"m")&" months, "&DATEDIF(M9,N9,"md")&" days" -> 5 months, 22 days
A10: 2026 OGA Contractor Tech 2.2.5 CEB | B10: CEB | C10: ='Tech 2.2.5 CEB'!$K$15 -> 20 | D10: ='Tech 2.2.5 CEB'!$K$13 -> 12249.99 | E10: =C10*D10 -> 244999.8 | F10: ='Tech 2.2.5 CEB'!$G$27 -> 0 | G10: ='Tech 2.2.5 CEB'!$G$51 -> 0 | H10: ='Tech 2.2.5 CEB'!$G$75 -> 0 | I10: =SUM(F10:H10) -> 0 | J10: ='Tech 2.2.5 CEB'!$K$4 -> 46318 | K10: ='Tech 2.2.5 CEB'!$K$5 -> 46349 | L10: ='Tech 2.2.5 CEB'!$K$6 -> 46416 | M10: ='Tech 2.2.5 CEB'!$K$3 -> 46269 | N10: ='Tech 2.2.5 CEB'!$K$6 -> 46416 | O10: =DATEDIF(M10,N10,"m")&" months, "&DATEDIF(M10,N10,"md")&" days" -> 4 months, 25 days
A11: 2026 OGA Contractor Tech 2.2.6 QC | B11: QC | C11: ='Tech 2.2.6 QC'!$K$15 -> 20 | D11: ='Tech 2.2.6 QC'!$K$13 -> 12249.99 | E11: =C11*D11 -> 244999.8 | F11: ='Tech 2.2.6 QC'!$G$27 -> 0 | G11: ='Tech 2.2.6 QC'!$G$51 -> 0 | H11: ='Tech 2.2.6 QC'!$G$75 -> 0 | I11: =SUM(F11:H11) -> 0 | J11: ='Tech 2.2.6 QC'!$K$4 -> 46325 | K11: ='Tech 2.2.6 QC'!$K$5 -> 46356 | L11: ='Tech 2.2.6 QC'!$K$6 -> 46423 | M11: ='Tech 2.2.6 QC'!$K$3 -> 46276 | N11: ='Tech 2.2.6 QC'!$K$6 -> 46423 | O11: =DATEDIF(M11,N11,"m")&" months, "&DATEDIF(M11,N11,"md")&" days" -> 4 months, 25 days
A12: 2026 OGA Contractor Tech 2.2.7 QC | B12: QC | C12: ='Tech 2.2.7 QC'!$K$15 -> 20 | D12: ='Tech 2.2.7 QC'!$K$13 -> 12249.99 | E12: =C12*D12 -> 244999.8 | F12: ='Tech 2.2.7 QC'!$G$27 -> 0 | G12: ='Tech 2.2.7 QC'!$G$51 -> 0 | H12: ='Tech 2.2.7 QC'!$G$75 -> 0 | I12: =SUM(F12:H12) -> 0 | J12: ='Tech 2.2.7 QC'!$K$4 -> 46325 | K12: ='Tech 2.2.7 QC'!$K$5 -> 46356 | L12: ='Tech 2.2.7 QC'!$K$6 -> 46423 | M12: ='Tech 2.2.7 QC'!$K$3 -> 46276 | N12: ='Tech 2.2.7 QC'!$K$6 -> 46423 | O12: =DATEDIF(M12,N12,"m")&" months, "&DATEDIF(M12,N12,"md")&" days" -> 4 months, 25 days
A13: 2026 OGA Contractor Tech 2.2.8 DVO | B13: DVO | C13: ='Tech 2.2.8 DVO'!$K$15 -> 20 | D13: ='Tech 2.2.8 DVO'!$K$13 -> 12250 | E13: =C13*D13 -> 245000 | F13: ='Tech 2.2.8 DVO'!$G$27 -> 0 | G13: ='Tech 2.2.8 DVO'!$G$51 -> 0 | H13: ='Tech 2.2.8 DVO'!$G$75 -> 0 | I13: =SUM(F13:H13) -> 0 | J13: ='Tech 2.2.8 DVO'!$K$4 -> 46332 | K13: ='Tech 2.2.8 DVO'!$K$5 -> 46362 | L13: ='Tech 2.2.8 DVO'!$K$6 -> 46430 | M13: ='Tech 2.2.8 DVO'!$K$3 -> 46283 | N13: ='Tech 2.2.8 DVO'!$K$6 -> 46430 | O13: =DATEDIF(M13,N13,"m")&" months, "&DATEDIF(M13,N13,"md")&" days" -> 4 months, 25 days
A14: 2026 OGA Contractor Tech 2.2.9 CEB | B14: CEB | C14: ='Tech 2.2.9 CEB'!$K$15 -> 15 | D14: ='Tech 2.2.9 CEB'!$K$13 -> 12250 | E14: =C14*D14 -> 183750 | F14: ='Tech 2.2.9 CEB'!$G$22 -> 0 | G14: ='Tech 2.2.9 CEB'!$G$41 -> 0 | H14: ='Tech 2.2.9 CEB'!$G$60 -> 0 | I14: =SUM(F14:H14) -> 0 | J14: ='Tech 2.2.9 CEB'!$K$4 -> 46332 | K14: ='Tech 2.2.9 CEB'!$K$5 -> 46362 | L14: ='Tech 2.2.9 CEB'!$K$6 -> 46430 | M14: ='Tech 2.2.9 CEB'!$K$3 -> 46283 | N14: ='Tech 2.2.9 CEB'!$K$6 -> 46430 | O14: =DATEDIF(M14,N14,"m")&" months, "&DATEDIF(M14,N14,"md")&" days" -> 4 months, 25 days
A15: 2026 OGA Contractor Tech 2.2.10 DVO | B15: DVO | C15: ='Tech 2.2.10 DVO'!$K$15 -> 20 | D15: ='Tech 2.2.10 DVO'!$K$13 -> 9916.66 | E15: =C15*D15 -> 198333.2 | F15: ='Tech 2.2.10 DVO'!$G$27 -> 0 | G15: ='Tech 2.2.10 DVO'!$G$51 -> 0 | H15: ='Tech 2.2.10 DVO'!$G$75 -> 0 | I15: =SUM(F15:H15) -> 0 | J15: ='Tech 2.2.10 DVO'!$K$4 -> 46353 | K15: ='Tech 2.2.10 DVO'!$K$5 -> 46383 | L15: ='Tech 2.2.10 DVO'!$K$6 -> 46423 | M15: ='Tech 2.2.10 DVO'!$K$3 -> 46304 | N15: ='Tech 2.2.10 DVO'!$K$6 -> 46423 | O15: =DATEDIF(M15,N15,"m")&" months, "&DATEDIF(M15,N15,"md")&" days" -> 3 months, 27 days
A16: 2026 OGA Contractor Tech 2.2.11 QC | B16: QC | C16: ='Tech 2.2.11 QC'!$K$15 -> 20 | D16: ='Tech 2.2.11 QC'!$K$13 -> 12083.33 | E16: =C16*D16 -> 241666.6 | F16: ='Tech 2.2.11 QC'!$G$27 -> 0 | G16: ='Tech 2.2.11 QC'!$G$51 -> 0 | H16: ='Tech 2.2.11 QC'!$G$75 -> 0 | I16: =SUM(F16:H16) -> 0 | J16: ='Tech 2.2.11 QC'!$K$4 -> 46339 | K16: ='Tech 2.2.11 QC'!$K$5 -> 46369 | L16: ='Tech 2.2.11 QC'!$K$6 -> 46435 | M16: ='Tech 2.2.11 QC'!$K$3 -> 46290 | N16: ='Tech 2.2.11 QC'!$K$6 -> 46435 | O16: =DATEDIF(M16,N16,"m")&" months, "&DATEDIF(M16,N16,"md")&" days" -> 4 months, 23 days
A17: GRAND TOTAL | E17: =SUM(E6:E16) -> 2770415.6 | I17: =SUM(I6:I16) -> 4083.33

Sheet Tech 2.2.1 CEB
A1: 2026 OGA Contractor Tech 2.2.1 CEB | Site: CEB | Tech HC: 20
J2: Milestone Schedule (input)
A3: Legend: | B3: Yellow = fill in per employee (Employee ID, Name, Scorecard Rating, With Active CAP?) | J3: NEO / Start Date | K3: 46227
J4: Tranche 1 Date (PST+OJT Complete) | K4: 46276
A5: TRANCHE 1 — Upon Passing PST + OJT | J5: Tranche 2 Date (+1 month) | K5: =EDATE(K4,1) -> 46306
A6: Supervisor | B6: Employee ID | C6: Name | D6: Scorecard Rating | E6: With Active CAP? | F6: Eligibility (Yes/No) | G6: Amount (PHP) | J6: Tranche 3 Date (Contract End) | K6: 46402
A7: Sarah | B7: 1805222 | C7: Jose Riza | D7: 3.5 | E7: No | F7: =IF(B7="","",IF(E7="","Pending",IF(E7="No","Yes","No"))) -> Yes | G7: =IF(F7="Yes",K10,0) -> 4083.33
A8: Sarah | F8: =IF(B8="","",IF(E8="","Pending",IF(E8="No","Yes","No"))) | G8: =IF(F8="Yes",K10,0) -> 0 | J8: Rate per Month (PHP) | K8: 2500
A9: Sarah | F9: =IF(B9="","",IF(E9="","Pending",IF(E9="No","Yes","No"))) | G9: =IF(F9="Yes",K10,0) -> 0
A10: Sarah | F10: =IF(B10="","",IF(E10="","Pending",IF(E10="No","Yes","No"))) | G10: =IF(F10="Yes",K10,0) -> 0 | J10: Tranche 1 Amount/Employee | K10: =ROUND((K4-K3)/30*$K$8,2) -> 4083.33
A11: Sarah | F11: =IF(B11="","",IF(E11="","Pending",IF(E11="No","Yes","No"))) | G11: =IF(F11="Yes",K10,0) -> 0 | J11: Tranche 2 Amount/Employee | K11: =ROUND((K5-K4)/30*$K$8,2) -> 2500
A12: Sarah | F12: =IF(B12="","",IF(E12="","Pending",IF(E12="No","Yes","No"))) | G12: =IF(F12="Yes",K10,0) -> 0 | J12: Tranche 3 Amount/Employee | K12: =ROUND(MAX(0,(K6-K5))/30*$K$8,2) -> 8000
A13: Sarah | F13: =IF(B13="","",IF(E13="","Pending",IF(E13="No","Yes","No"))) | G13: =IF(F13="Yes",K10,0) -> 0 | J13: Total Potential/Employee | K13: =SUM(K10:K12) -> 14583.33
A14: Sarah | F14: =IF(B14="","",IF(E14="","Pending",IF(E14="No","Yes","No"))) | G14: =IF(F14="Yes",K10,0) -> 0
A15: Sarah | F15: =IF(B15="","",IF(E15="","Pending",IF(E15="No","Yes","No"))) | G15: =IF(F15="Yes",K10,0) -> 0 | J15: Tech HC (from Gantt, excludes Support HC) | K15: 20
A16: Sarah | F16: =IF(B16="","",IF(E16="","Pending",IF(E16="No","Yes","No"))) | G16: =IF(F16="Yes",K10,0) -> 0
A17: Sarah | F17: =IF(B17="","",IF(E17="","Pending",IF(E17="No","Yes","No"))) | G17: =IF(F17="Yes",K10,0) -> 0 | J17: Note: Tranche 1 amount = elapsed months from NEO to PST+OJT completion x PHP2,500.
A18: Sarah | F18: =IF(B18="","",IF(E18="","Pending",IF(E18="No","Yes","No"))) | G18: =IF(F18="Yes",K10,0) -> 0 | J18: Tranche 2 = 1 month later. Tranche 3 = elapsed months from Tranche 2 to Contract End (prorated).
A19: Sarah | F19: =IF(B19="","",IF(E19="","Pending",IF(E19="No","Yes","No"))) | G19: =IF(F19="Yes",K10,0) -> 0 | J19: Tranche 1 eligibility = no active CAP (per contract, no scorecard gate).
A20: Sarah | F20: =IF(B20="","",IF(E20="","Pending",IF(E20="No","Yes","No"))) | G20: =IF(F20="Yes",K10,0) -> 0 | J20: Tranche 2 & 3 eligibility = Scorecard >=3.0 AND no active CAP.
A21: Sarah | F21: =IF(B21="","",IF(E21="","Pending",IF(E21="No","Yes","No"))) | G21: =IF(F21="Yes",K10,0) -> 0 | J21: Row 7 on this tab (Tranche 1) shows an example — replace with real data.
A22: Sarah | F22: =IF(B22="","",IF(E22="","Pending",IF(E22="No","Yes","No"))) | G22: =IF(F22="Yes",K10,0) -> 0
A23: Sarah | F23: =IF(B23="","",IF(E23="","Pending",IF(E23="No","Yes","No"))) | G23: =IF(F23="Yes",K10,0) -> 0
A24: Sarah | F24: =IF(B24="","",IF(E24="","Pending",IF(E24="No","Yes","No"))) | G24: =IF(F24="Yes",K10,0) -> 0
A25: Sarah | F25: =IF(B25="","",IF(E25="","Pending",IF(E25="No","Yes","No"))) | G25: =IF(F25="Yes",K10,0) -> 0
A26: Sarah | F26: =IF(B26="","",IF(E26="","Pending",IF(E26="No","Yes","No"))) | G26: =IF(F26="Yes",K10,0) -> 0
A27: Subtotal | G27: =SUM(G7:G26) -> 4083.33
A29: TRANCHE 2 — 1 Month After Tranche 1 (Scorecard-gated)
A30: Supervisor | B30: Employee ID | C30: Name | D30: Scorecard Rating | E30: With Active CAP? | F30: Eligibility (Yes/No) | G30: Amount (PHP)
A31: Sarah | F31: =IF(B31="","",IF(OR(D31="",E31=""),"Pending",IF(AND(D31>=3,E31="No"),"Yes","No"))) | G31: =IF(F31="Yes",K11,0) -> 0
A32: Sarah | F32: =IF(B32="","",IF(OR(D32="",E32=""),"Pending",IF(AND(D32>=3,E32="No"),"Yes","No"))) | G32: =IF(F32="Yes",K11,0) -> 0
A33: Sarah | F33: =IF(B33="","",IF(OR(D33="",E33=""),"Pending",IF(AND(D33>=3,E33="No"),"Yes","No"))) | G33: =IF(F33="Yes",K11,0) -> 0
A34: Sarah | F34: =IF(B34="","",IF(OR(D34="",E34=""),"Pending",IF(AND(D34>=3,E34="No"),"Yes","No"))) | G34: =IF(F34="Yes",K11,0) -> 0
A35: Sarah | F35: =IF(B35="","",IF(OR(D35="",E35=""),"Pending",IF(AND(D35>=3,E35="No"),"Yes","No"))) | G35: =IF(F35="Yes",K11,0) -> 0
A36: Sarah | F36: =IF(B36="","",IF(OR(D36="",E36=""),"Pending",IF(AND(D36>=3,E36="No"),"Yes","No"))) | G36: =IF(F36="Yes",K11,0) -> 0
A37: Sarah | F37: =IF(B37="","",IF(OR(D37="",E37=""),"Pending",IF(AND(D37>=3,E37="No"),"Yes","No"))) | G37: =IF(F37="Yes",K11,0) -> 0
A38: Sarah | F38: =IF(B38="","",IF(OR(D38="",E38=""),"Pending",IF(AND(D38>=3,E38="No"),"Yes","No"))) | G38: =IF(F38="Yes",K11,0) -> 0
A39: Sarah | F39: =IF(B39="","",IF(OR(D39="",E39=""),"Pending",IF(AND(D39>=3,E39="No"),"Yes","No"))) | G39: =IF(F39="Yes",K11,0) -> 0
A40: Sarah | F40: =IF(B40="","",IF(OR(D40="",E40=""),"Pending",IF(AND(D40>=3,E40="No"),"Yes","No"))) | G40: =IF(F40="Yes",K11,0) -> 0
A41: Sarah | F41: =IF(B41="","",IF(OR(D41="",E41=""),"Pending",IF(AND(D41>=3,E41="No"),"Yes","No"))) | G41: =IF(F41="Yes",K11,0) -> 0
...

Sheet Tech 2.2.2 CEB
A1: 2026 OGA Contractor Tech 2.2.2 CEB | Site: CEB | Tech HC: 20
J2: Milestone Schedule (input)
A3: Legend: | B3: Yellow = fill in per employee (Employee ID, Name, Scorecard Rating, With Active CAP?) | J3: NEO / Start Date | K3: 46248
J4: Tranche 1 Date (PST+OJT Complete) | K4: 46297
A5: TRANCHE 1 — Upon Passing PST + OJT | J5: Tranche 2 Date (+1 month) | K5: =EDATE(K4,1) -> 46328
A6: Supervisor | B6: Employee ID | C6: Name | D6: Scorecard Rating | E6: With Active CAP? | F6: Eligibility (Yes/No) | G6: Amount (PHP) | J6: Tranche 3 Date (Contract End) | K6: 46423
A7: Sarah | F7: =IF(B7="","",IF(E7="","Pending",IF(E7="No","Yes","No"))) | G7: =IF(F7="Yes",K10,0) -> 0
A8: Sarah | F8: =IF(B8="","",IF(E8="","Pending",IF(E8="No","Yes","No"))) | G8: =IF(F8="Yes",K10,0) -> 0 | J8: Rate per Month (PHP) | K8: 2500
A9: Sarah | F9: =IF(B9="","",IF(E9="","Pending",IF(E9="No","Yes","No"))) | G9: =IF(F9="Yes",K10,0) -> 0
A10: Sarah | F10: =IF(B10="","",IF(E10="","Pending",IF(E10="No","Yes","No"))) | G10: =IF(F10="Yes",K10,0) -> 0 | J10: Tranche 1 Amount/Employee | K10: =ROUND((K4-K3)/30*$K$8,2) -> 4083.33
A11: Sarah | F11: =IF(B11="","",IF(E11="","Pending",IF(E11="No","Yes","No"))) | G11: =IF(F11="Yes",K10,0) -> 0 | J11: Tranche 2 Amount/Employee | K11: =ROUND((K5-K4)/30*$K$8,2) -> 2583.33
A12: Sarah | F12: =IF(B12="","",IF(E12="","Pending",IF(E12="No","Yes","No"))) | G12: =IF(F12="Yes",K10,0) -> 0 | J12: Tranche 3 Amount/Employee | K12: =ROUND(MAX(0,(K6-K5))/30*$K$8,2) -> 7916.67
A13: Sarah | F13: =IF(B13="","",IF(E13="","Pending",IF(E13="No","Yes","No"))) | G13: =IF(F13="Yes",K10,0) -> 0 | J13: Total Potential/Employee | K13: =SUM(K10:K12) -> 14583.33
A14: Sarah | F14: =IF(B14="","",IF(E14="","Pending",IF(E14="No","Yes","No"))) | G14: =IF(F14="Yes",K10,0) -> 0
A15: Sarah | F15: =IF(B15="","",IF(E15="","Pending",IF(E15="No","Yes","No"))) | G15: =IF(F15="Yes",K10,0) -> 0 | J15: Tech HC (from Gantt, excludes Support HC) | K15: 20
A16: Sarah | F16: =IF(B16="","",IF(E16="","Pending",IF(E16="No","Yes","No"))) | G16: =IF(F16="Yes",K10,0) -> 0
A17: Sarah | F17: =IF(B17="","",IF(E17="","Pending",IF(E17="No","Yes","No"))) | G17: =IF(F17="Yes",K10,0) -> 0 | J17: Note: Tranche 1 amount = elapsed months from NEO to PST+OJT completion x PHP2,500.
A18: Sarah | F18: =IF(B18="","",IF(E18="","Pending",IF(E18="No","Yes","No"))) | G18: =IF(F18="Yes",K10,0) -> 0 | J18: Tranche 2 = 1 month later. Tranche 3 = elapsed months from Tranche 2 to Contract End (prorated).
A19: Sarah | F19: =IF(B19="","",IF(E19="","Pending",IF(E19="No","Yes","No"))) | G19: =IF(F19="Yes",K10,0) -> 0 | J19: Tranche 1 eligibility = no active CAP (per contract, no scorecard gate).
A20: Sarah | F20: =IF(B20="","",IF(E20="","Pending",IF(E20="No","Yes","No"))) | G20: =IF(F20="Yes",K10,0) -> 0 | J20: Tranche 2 & 3 eligibility = Scorecard >=3.0 AND no active CAP.
A21: Sarah | F21: =IF(B21="","",IF(E21="","Pending",IF(E21="No","Yes","No"))) | G21: =IF(F21="Yes",K10,0) -> 0
A22: Sarah | F22: =IF(B22="","",IF(E22="","Pending",IF(E22="No","Yes","No"))) | G22: =IF(F22="Yes",K10,0) -> 0
A23: Sarah | F23: =IF(B23="","",IF(E23="","Pending",IF(E23="No","Yes","No"))) | G23: =IF(F23="Yes",K10,0) -> 0
A24: Sarah | F24: =IF(B24="","",IF(E24="","Pending",IF(E24="No","Yes","No"))) | G24: =IF(F24="Yes",K10,0) -> 0
A25: Sarah | F25: =IF(B25="","",IF(E25="","Pending",IF(E25="No","Yes","No"))) | G25: =IF(F25="Yes",K10,0) -> 0
A26: Sarah | F26: =IF(B26="","",IF(E26="","Pending",IF(E26="No","Yes","No"))) | G26: =IF(F26="Yes",K10,0) -> 0
A27: Subtotal | G27: =SUM(G7:G26) -> 0
A29: TRANCHE 2 — 1 Month After Tranche 1 (Scorecard-gated)
A30: Supervisor | B30: Employee ID | C30: Name | D30: Scorecard Rating | E30: With Active CAP? | F30: Eligibility (Yes/No) | G30: Amount (PHP)
A31: Sarah | F31: =IF(B31="","",IF(OR(D31="",E31=""),"Pending",IF(AND(D31>=3,E31="No"),"Yes","No"))) | G31: =IF(F31="Yes",K11,0) -> 0
A32: Sarah | F32: =IF(B32="","",IF(OR(D32="",E32=""),"Pending",IF(AND(D32>=3,E32="No"),"Yes","No"))) | G32: =IF(F32="Yes",K11,0) -> 0
A33: Sarah | F33: =IF(B33="","",IF(OR(D33="",E33=""),"Pending",IF(AND(D33>=3,E33="No"),"Yes","No"))) | G33: =IF(F33="Yes",K11,0) -> 0
A34: Sarah | F34: =IF(B34="","",IF(OR(D34="",E34=""),"Pending",IF(AND(D34>=3,E34="No"),"Yes","No"))) | G34: =IF(F34="Yes",K11,0) -> 0
A35: Sarah | F35: =IF(B35="","",IF(OR(D35="",E35=""),"Pending",IF(AND(D35>=3,E35="No"),"Yes","No"))) | G35: =IF(F35="Yes",K11,0) -> 0
A36: Sarah | F36: =IF(B36="","",IF(OR(D36="",E36=""),"Pending",IF(AND(D36>=3,E36="No"),"Yes","No"))) | G36: =IF(F36="Yes",K11,0) -> 0
A37: Sarah | F37: =IF(B37="","",IF(OR(D37="",E37=""),"Pending",IF(AND(D37>=3,E37="No"),"Yes","No"))) | G37: =IF(F37="Yes",K11,0) -> 0
A38: Sarah | F38: =IF(B38="","",IF(OR(D38="",E38=""),"Pending",IF(AND(D38>=3,E38="No"),"Yes","No"))) | G38: =IF(F38="Yes",K11,0) -> 0
A39: Sarah | F39: =IF(B39="","",IF(OR(D39="",E39=""),"Pending",IF(AND(D39>=3,E39="No"),"Yes","No"))) | G39: =IF(F39="Yes",K11,0) -> 0
A40: Sarah | F40: =IF(B40="","",IF(OR(D40="",E40=""),"Pending",IF(AND(D40>=3,E40="No"),"Yes","No"))) | G40: =IF(F40="Yes",K11,0) -> 0
A41: Sarah | F41: =IF(B41="","",IF(OR(D41="",E41=""),"Pending",IF(AND(D41>=3,E41="No"),"Yes","No"))) | G41: =IF(F41="Yes",K11,0) -> 0
...

Sheet Tech 2.2.3 CEB
A1: 2026 OGA Contractor Tech 2.2.3 CEB | Site: CEB | Tech HC: 20
J2: Milestone Schedule (input)
A3: Legend: | B3: Yellow = fill in per employee (Employee ID, Name, Scorecard Rating, With Active CAP?) | J3: NEO / Start Date | K3: 46255
J4: Tranche 1 Date (PST+OJT Complete) | K4: 46304
A5: TRANCHE 1 — Upon Passing PST + OJT | J5: Tranche 2 Date (+1 month) | K5: =EDATE(K4,1) -> 46335
A6: Supervisor | B6: Employee ID | C6: Name | D6: Scorecard Rating | E6: With Active CAP? | F6: Eligibility (Yes/No) | G6: Amount (PHP) | J6: Tranche 3 Date (Contract End) | K6: 46430
A7: Sarah | F7: =IF(B7="","",IF(E7="","Pending",IF(E7="No","Yes","No"))) | G7: =IF(F7="Yes",K10,0) -> 0
A8: Sarah | F8: =IF(B8="","",IF(E8="","Pending",IF(E8="No","Yes","No"))) | G8: =IF(F8="Yes",K10,0) -> 0 | J8: Rate per Month (PHP) | K8: 2500
A9: Sarah | F9: =IF(B9="","",IF(E9="","Pending",IF(E9="No","Yes","No"))) | G9: =IF(F9="Yes",K10,0) -> 0
A10: Sarah | F10: =IF(B10="","",IF(E10="","Pending",IF(E10="No","Yes","No"))) | G10: =IF(F10="Yes",K10,0) -> 0 | J10: Tranche 1 Amount/Employee | K10: =ROUND((K4-K3)/30*$K$8,2) -> 4083.33
A11: Sarah | F11: =IF(B11="","",IF(E11="","Pending",IF(E11="No","Yes","No"))) | G11: =IF(F11="Yes",K10,0) -> 0 | J11: Tranche 2 Amount/Employee | K11: =ROUND((K5-K4)/30*$K$8,2) -> 2583.33
A12: Sarah | F12: =IF(B12="","",IF(E12="","Pending",IF(E12="No","Yes","No"))) | G12: =IF(F12="Yes",K10,0) -> 0 | J12: Tranche 3 Amount/Employee | K12: =ROUND(MAX(0,(K6-K5))/30*$K$8,2) -> 7916.67
A13: Sarah | F13: =IF(B13="","",IF(E13="","Pending",IF(E13="No","Yes","No"))) | G13: =IF(F13="Yes",K10,0) -> 0 | J13: Total Potential/Employee | K13: =SUM(K10:K12) -> 14583.33
A14: Sarah | F14: =IF(B14="","",IF(E14="","Pending",IF(E14="No","Yes","No"))) | G14: =IF(F14="Yes",K10,0) -> 0
A15: Sarah | F15: =IF(B15="","",IF(E15="","Pending",IF(E15="No","Yes","No"))) | G15: =IF(F15="Yes",K10,0) -> 0 | J15: Tech HC (from Gantt, excludes Support HC) | K15: 20
A16: Sarah | F16: =IF(B16="","",IF(E16="","Pending",IF(E16="No","Yes","No"))) | G16: =IF(F16="Yes",K10,0) -> 0
A17: Sarah | F17: =IF(B17="","",IF(E17="","Pending",IF(E17="No","Yes","No"))) | G17: =IF(F17="Yes",K10,0) -> 0 | J17: Note: Tranche 1 amount = elapsed months from NEO to PST+OJT completion x PHP2,500.
A18: Sarah | F18: =IF(B18="","",IF(E18="","Pending",IF(E18="No","Yes","No"))) | G18: =IF(F18="Yes",K10,0) -> 0 | J18: Tranche 2 = 1 month later. Tranche 3 = elapsed months from Tranche 2 to Contract End (prorated).
A19: Sarah | F19: =IF(B19="","",IF(E19="","Pending",IF(E19="No","Yes","No"))) | G19: =IF(F19="Yes",K10,0) -> 0 | J19: Tranche 1 eligibility = no active CAP (per contract, no scorecard gate).
A20: Sarah | F20: =IF(B20="","",IF(E20="","Pending",IF(E20="No","Yes","No"))) | G20: =IF(F20="Yes",K10,0) -> 0 | J20: Tranche 2 & 3 eligibility = Scorecard >=3.0 AND no active CAP.
A21: Sarah | F21: =IF(B21="","",IF(E21="","Pending",IF(E21="No","Yes","No"))) | G21: =IF(F21="Yes",K10,0) -> 0
A22: Sarah | F22: =IF(B22="","",IF(E22="","Pending",IF(E22="No","Yes","No"))) | G22: =IF(F22="Yes",K10,0) -> 0
A23: Sarah | F23: =IF(B23="","",IF(E23="","Pending",IF(E23="No","Yes","No"))) | G23: =IF(F23="Yes",K10,0) -> 0
A24: Sarah | F24: =IF(B24="","",IF(E24="","Pending",IF(E24="No","Yes","No"))) | G24: =IF(F24="Yes",K10,0) -> 0
A25: Sarah | F25: =IF(B25="","",IF(E25="","Pending",IF(E25="No","Yes","No"))) | G25: =IF(F25="Yes",K10,0) -> 0
A26: Sarah | F26: =IF(B26="","",IF(E26="","Pending",IF(E26="No","Yes","No"))) | G26: =IF(F26="Yes",K10,0) -> 0
A27: Subtotal | G27: =SUM(G7:G26) -> 0
A29: TRANCHE 2 — 1 Month After Tranche 1 (Scorecard-gated)
A30: Supervisor | B30: Employee ID | C30: Name | D30: Scorecard Rating | E30: With Active CAP? | F30: Eligibility (Yes/No) | G30: Amount (PHP)
A31: Sarah | F31: =IF(B31="","",IF(OR(D31="",E31=""),"Pending",IF(AND(D31>=3,E31="No"),"Yes","No"))) | G31: =IF(F31="Yes",K11,0) -> 0
A32: Sarah | F32: =IF(B32="","",IF(OR(D32="",E32=""),"Pending",IF(AND(D32>=3,E32="No"),"Yes","No"))) | G32: =IF(F32="Yes",K11,0) -> 0
A33: Sarah | F33: =IF(B33="","",IF(OR(D33="",E33=""),"Pending",IF(AND(D33>=3,E33="No"),"Yes","No"))) | G33: =IF(F33="Yes",K11,0) -> 0
A34: Sarah | F34: =IF(B34="","",IF(OR(D34="",E34=""),"Pending",IF(AND(D34>=3,E34="No"),"Yes","No"))) | G34: =IF(F34="Yes",K11,0) -> 0
A35: Sarah | F35: =IF(B35="","",IF(OR(D35="",E35=""),"Pending",IF(AND(D35>=3,E35="No"),"Yes","No"))) | G35: =IF(F35="Yes",K11,0) -> 0
A36: Sarah | F36: =IF(B36="","",IF(OR(D36="",E36=""),"Pending",IF(AND(D36>=3,E36="No"),"Yes","No"))) | G36: =IF(F36="Yes",K11,0) -> 0
A37: Sarah | F37: =IF(B37="","",IF(OR(D37="",E37=""),"Pending",IF(AND(D37>=3,E37="No"),"Yes","No"))) | G37: =IF(F37="Yes",K11,0) -> 0
A38: Sarah | F38: =IF(B38="","",IF(OR(D38="",E38=""),"Pending",IF(AND(D38>=3,E38="No"),"Yes","No"))) | G38: =IF(F38="Yes",K11,0) -> 0
A39: Sarah | F39: =IF(B39="","",IF(OR(D39="",E39=""),"Pending",IF(AND(D39>=3,E39="No"),"Yes","No"))) | G39: =IF(F39="Yes",K11,0) -> 0
A40: Sarah | F40: =IF(B40="","",IF(OR(D40="",E40=""),"Pending",IF(AND(D40>=3,E40="No"),"Yes","No"))) | G40: =IF(F40="Yes",K11,0) -> 0
A41: Sarah | F41: =IF(B41="","",IF(OR(D41="",E41=""),"Pending",IF(AND(D41>=3,E41="No"),"Yes","No"))) | G41: =IF(F41="Yes",K11,0) -> 0
...

Sheet Tech 2.2.4 QC
A1: 2026 OGA Contractor Tech 2.2.4 QC | Site: QC | Tech HC: 20
J2: Milestone Schedule (input)
A3: Legend: | B3: Yellow = fill in per employee (Employee ID, Name, Scorecard Rating, With Active CAP?) | J3: NEO / Start Date | K3: 46262
J4: Tranche 1 Date (PST+OJT Complete) | K4: 46311
A5: TRANCHE 1 — Upon Passing PST + OJT | J5: Tranche 2 Date (+1 month) | K5: =EDATE(K4,1) -> 46342
A6: Supervisor | B6: Employee ID | C6: Name | D6: Scorecard Rating | E6: With Active CAP? | F6: Eligibility (Yes/No) | G6: Amount (PHP) | J6: Tranche 3 Date (Contract End) | K6: 46437
A7: Sarah | F7: =IF(B7="","",IF(E7="","Pending",IF(E7="No","Yes","No"))) | G7: =IF(F7="Yes",K10,0) -> 0
A8: Sarah | F8: =IF(B8="","",IF(E8="","Pending",IF(E8="No","Yes","No"))) | G8: =IF(F8="Yes",K10,0) -> 0 | J8: Rate per Month (PHP) | K8: 2500
A9: Sarah | F9: =IF(B9="","",IF(E9="","Pending",IF(E9="No","Yes","No"))) | G9: =IF(F9="Yes",K10,0) -> 0
A10: Sarah | F10: =IF(B10="","",IF(E10="","Pending",IF(E10="No","Yes","No"))) | G10: =IF(F10="Yes",K10,0) -> 0 | J10: Tranche 1 Amount/Employee | K10: =ROUND((K4-K3)/30*$K$8,2) -> 4083.33
A11: Sarah | F11: =IF(B11="","",IF(E11="","Pending",IF(E11="No","Yes","No"))) | G11: =IF(F11="Yes",K10,0) -> 0 | J11: Tranche 2 Amount/Employee | K11: =ROUND((K5-K4)/30*$K$8,2) -> 2583.33
A12: Sarah | F12: =IF(B12="","",IF(E12="","Pending",IF(E12="No","Yes","No"))) | G12: =IF(F12="Yes",K10,0) -> 0 | J12: Tranche 3 Amount/Employee | K12: =ROUND(MAX(0,(K6-K5))/30*$K$8,2) -> 7916.67
A13: Sarah | F13: =IF(B13="","",IF(E13="","Pending",IF(E13="No","Yes","No"))) | G13: =IF(F13="Yes",K10,0) -> 0 | J13: Total Potential/Employee | K13: =SUM(K10:K12) -> 14583.33
A14: Sarah | F14: =IF(B14="","",IF(E14="","Pending",IF(E14="No","Yes","No"))) | G14: =IF(F14="Yes",K10,0) -> 0
A15: Sarah | F15: =IF(B15="","",IF(E15="","Pending",IF(E15="No","Yes","No"))) | G15: =IF(F15="Yes",K10,0) -> 0 | J15: Tech HC (from Gantt, excludes Support HC) | K15: 20
A16: Sarah | F16: =IF(B16="","",IF(E16="","Pending",IF(E16="No","Yes","No"))) | G16: =IF(F16="Yes",K10,0) -> 0
A17: Sarah | F17: =IF(B17="","",IF(E17="","Pending",IF(E17="No","Yes","No"))) | G17: =IF(F17="Yes",K10,0) -> 0 | J17: Note: Tranche 1 amount = elapsed months from NEO to PST+OJT completion x PHP2,500.
A18: Sarah | F18: =IF(B18="","",IF(E18="","Pending",IF(E18="No","Yes","No"))) | G18: =IF(F18="Yes",K10,0) -> 0 | J18: Tranche 2 = 1 month later. Tranche 3 = elapsed months from Tranche 2 to Contract End (prorated).
A19: Sarah | F19: =IF(B19="","",IF(E19="","Pending",IF(E19="No","Yes","No"))) | G19: =IF(F19="Yes",K10,0) -> 0 | J19: Tranche 1 eligibility = no active CAP (per contract, no scorecard gate).
A20: Sarah | F20: =IF(B20="","",IF(E20="","Pending",IF(E20="No","Yes","No"))) | G20: =IF(F20="Yes",K10,0) -> 0 | J20: Tranche 2 & 3 eligibility = Scorecard >=3.0 AND no active CAP.
A21: Sarah | F21: =IF(B21="","",IF(E21="","Pending",IF(E21="No","Yes","No"))) | G21: =IF(F21="Yes",K10,0) -> 0
A22: Sarah | F22: =IF(B22="","",IF(E22="","Pending",IF(E22="No","Yes","No"))) | G22: =IF(F22="Yes",K10,0) -> 0
A23: Sarah | F23: =IF(B23="","",IF(E23="","Pending",IF(E23="No","Yes","No"))) | G23: =IF(F23="Yes",K10,0) -> 0
A24: Sarah | F24: =IF(B24="","",IF(E24="","Pending",IF(E24="No","Yes","No"))) | G24: =IF(F24="Yes",K10,0) -> 0
A25: Sarah | F25: =IF(B25="","",IF(E25="","Pending",IF(E25="No","Yes","No"))) | G25: =IF(F25="Yes",K10,0) -> 0
A26: Sarah | F26: =IF(B26="","",IF(E26="","Pending",IF(E26="No","Yes","No"))) | G26: =IF(F26="Yes",K10,0) -> 0
A27: Subtotal | G27: =SUM(G7:G26) -> 0
A29: TRANCHE 2 — 1 Month After Tranche 1 (Scorecard-gated)
A30: Supervisor | B30: Employee ID | C30: Name | D30: Scorecard Rating | E30: With Active CAP? | F30: Eligibility (Yes/No) | G30: Amount (PHP)
A31: Sarah | F31: =IF(B31="","",IF(OR(D31="",E31=""),"Pending",IF(AND(D31>=3,E31="No"),"Yes","No"))) | G31: =IF(F31="Yes",K11,0) -> 0
A32: Sarah | F32: =IF(B32="","",IF(OR(D32="",E32=""),"Pending",IF(AND(D32>=3,E32="No"),"Yes","No"))) | G32: =IF(F32="Yes",K11,0) -> 0
A33: Sarah | F33: =IF(B33="","",IF(OR(D33="",E33=""),"Pending",IF(AND(D33>=3,E33="No"),"Yes","No"))) | G33: =IF(F33="Yes",K11,0) -> 0
A34: Sarah | F34: =IF(B34="","",IF(OR(D34="",E34=""),"Pending",IF(AND(D34>=3,E34="No"),"Yes","No"))) | G34: =IF(F34="Yes",K11,0) -> 0
A35: Sarah | F35: =IF(B35="","",IF(OR(D35="",E35=""),"Pending",IF(AND(D35>=3,E35="No"),"Yes","No"))) | G35: =IF(F35="Yes",K11,0) -> 0
A36: Sarah | F36: =IF(B36="","",IF(OR(D36="",E36=""),"Pending",IF(AND(D36>=3,E36="No"),"Yes","No"))) | G36: =IF(F36="Yes",K11,0) -> 0
A37: Sarah | F37: =IF(B37="","",IF(OR(D37="",E37=""),"Pending",IF(AND(D37>=3,E37="No"),"Yes","No"))) | G37: =IF(F37="Yes",K11,0) -> 0
A38: Sarah | F38: =IF(B38="","",IF(OR(D38="",E38=""),"Pending",IF(AND(D38>=3,E38="No"),"Yes","No"))) | G38: =IF(F38="Yes",K11,0) -> 0
A39: Sarah | F39: =IF(B39="","",IF(OR(D39="",E39=""),"Pending",IF(AND(D39>=3,E39="No"),"Yes","No"))) | G39: =IF(F39="Yes",K11,0) -> 0
A40: Sarah | F40: =IF(B40="","",IF(OR(D40="",E40=""),"Pending",IF(AND(D40>=3,E40="No"),"Yes","No"))) | G40: =IF(F40="Yes",K11,0) -> 0
A41: Sarah | F41: =IF(B41="","",IF(OR(D41="",E41=""),"Pending",IF(AND(D41>=3,E41="No"),"Yes","No"))) | G41: =IF(F41="Yes",K11,0) -> 0
...

Sheet Tech 2.2.5 CEB
A1: 2026 OGA Contractor Tech 2.2.5 CEB | Site: CEB | Tech HC: 20
J2: Milestone Schedule (input)
A3: Legend: | B3: Yellow = fill in per employee (Employee ID, Name, Scorecard Rating, With Active CAP?) | J3: NEO / Start Date | K3: 46269
J4: Tranche 1 Date (PST+OJT Complete) | K4: 46318
A5: TRANCHE 1 — Upon Passing PST + OJT | J5: Tranche 2 Date (+1 month) | K5: =EDATE(K4,1) -> 46349
A6: Supervisor | B6: Employee ID | C6: Name | D6: Scorecard Rating | E6: With Active CAP? | F6: Eligibility (Yes/No) | G6: Amount (PHP) | J6: Tranche 3 Date (Contract End) | K6: 46416
A7: Sarah | F7: =IF(B7="","",IF(E7="","Pending",IF(E7="No","Yes","No"))) | G7: =IF(F7="Yes",K10,0) -> 0
A8: Sarah | F8: =IF(B8="","",IF(E8="","Pending",IF(E8="No","Yes","No"))) | G8: =IF(F8="Yes",K10,0) -> 0 | J8: Rate per Month (PHP) | K8: 2500
A9: Sarah | F9: =IF(B9="","",IF(E9="","Pending",IF(E9="No","Yes","No"))) | G9: =IF(F9="Yes",K10,0) -> 0
A10: Sarah | F10: =IF(B10="","",IF(E10="","Pending",IF(E10="No","Yes","No"))) | G10: =IF(F10="Yes",K10,0) -> 0 | J10: Tranche 1 Amount/Employee | K10: =ROUND((K4-K3)/30*$K$8,2) -> 4083.33
A11: Sarah | F11: =IF(B11="","",IF(E11="","Pending",IF(E11="No","Yes","No"))) | G11: =IF(F11="Yes",K10,0) -> 0 | J11: Tranche 2 Amount/Employee | K11: =ROUND((K5-K4)/30*$K$8,2) -> 2583.33
A12: Sarah | F12: =IF(B12="","",IF(E12="","Pending",IF(E12="No","Yes","No"))) | G12: =IF(F12="Yes",K10,0) -> 0 | J12: Tranche 3 Amount/Employee | K12: =ROUND(MAX(0,(K6-K5))/30*$K$8,2) -> 5583.33
A13: Sarah | F13: =IF(B13="","",IF(E13="","Pending",IF(E13="No","Yes","No"))) | G13: =IF(F13="Yes",K10,0) -> 0 | J13: Total Potential/Employee | K13: =SUM(K10:K12) -> 12249.99
A14: Sarah | F14: =IF(B14="","",IF(E14="","Pending",IF(E14="No","Yes","No"))) | G14: =IF(F14="Yes",K10,0) -> 0
A15: Sarah | F15: =IF(B15="","",IF(E15="","Pending",IF(E15="No","Yes","No"))) | G15: =IF(F15="Yes",K10,0) -> 0 | J15: Tech HC (from Gantt, excludes Support HC) | K15: 20
A16: Sarah | F16: =IF(B16="","",IF(E16="","Pending",IF(E16="No","Yes","No"))) | G16: =IF(F16="Yes",K10,0) -> 0
A17: Sarah | F17: =IF(B17="","",IF(E17="","Pending",IF(E17="No","Yes","No"))) | G17: =IF(F17="Yes",K10,0) -> 0 | J17: Note: Tranche 1 amount = elapsed months from NEO to PST+OJT completion x PHP2,500.
A18: Sarah | F18: =IF(B18="","",IF(E18="","Pending",IF(E18="No","Yes","No"))) | G18: =IF(F18="Yes",K10,0) -> 0 | J18: Tranche 2 = 1 month later. Tranche 3 = elapsed months from Tranche 2 to Contract End (prorated).
A19: Sarah | F19: =IF(B19="","",IF(E19="","Pending",IF(E19="No","Yes","No"))) | G19: =IF(F19="Yes",K10,0) -> 0 | J19: Tranche 1 eligibility = no active CAP (per contract, no scorecard gate).
A20: Sarah | F20: =IF(B20="","",IF(E20="","Pending",IF(E20="No","Yes","No"))) | G20: =IF(F20="Yes",K10,0) -> 0 | J20: Tranche 2 & 3 eligibility = Scorecard >=3.0 AND no active CAP.
A21: Sarah | F21: =IF(B21="","",IF(E21="","Pending",IF(E21="No","Yes","No"))) | G21: =IF(F21="Yes",K10,0) -> 0
A22: Sarah | F22: =IF(B22="","",IF(E22="","Pending",IF(E22="No","Yes","No"))) | G22: =IF(F22="Yes",K10,0) -> 0
A23: Sarah | F23: =IF(B23="","",IF(E23="","Pending",IF(E23="No","Yes","No"))) | G23: =IF(F23="Yes",K10,0) -> 0
A24: Sarah | F24: =IF(B24="","",IF(E24="","Pending",IF(E24="No","Yes","No"))) | G24: =IF(F24="Yes",K10,0) -> 0
A25: Sarah | F25: =IF(B25="","",IF(E25="","Pending",IF(E25="No","Yes","No"))) | G25: =IF(F25="Yes",K10,0) -> 0
A26: Sarah | F26: =IF(B26="","",IF(E26="","Pending",IF(E26="No","Yes","No"))) | G26: =IF(F26="Yes",K10,0) -> 0
A27: Subtotal | G27: =SUM(G7:G26) -> 0
A29: TRANCHE 2 — 1 Month After Tranche 1 (Scorecard-gated)
A30: Supervisor | B30: Employee ID | C30: Name | D30: Scorecard Rating | E30: With Active CAP? | F30: Eligibility (Yes/No) | G30: Amount (PHP)
A31: Sarah | F31: =IF(B31="","",IF(OR(D31="",E31=""),"Pending",IF(AND(D31>=3,E31="No"),"Yes","No"))) | G31: =IF(F31="Yes",K11,0) -> 0
A32: Sarah | F32: =IF(B32="","",IF(OR(D32="",E32=""),"Pending",IF(AND(D32>=3,E32="No"),"Yes","No"))) | G32: =IF(F32="Yes",K11,0) -> 0
A33: Sarah | F33: =IF(B33="","",IF(OR(D33="",E33=""),"Pending",IF(AND(D33>=3,E33="No"),"Yes","No"))) | G33: =IF(F33="Yes",K11,0) -> 0
A34: Sarah | F34: =IF(B34="","",IF(OR(D34="",E34=""),"Pending",IF(AND(D34>=3,E34="No"),"Yes","No"))) | G34: =IF(F34="Yes",K11,0) -> 0
A35: Sarah | F35: =IF(B35="","",IF(OR(D35="",E35=""),"Pending",IF(AND(D35>=3,E35="No"),"Yes","No"))) | G35: =IF(F35="Yes",K11,0) -> 0
A36: Sarah | F36: =IF(B36="","",IF(OR(D36="",E36=""),"Pending",IF(AND(D36>=3,E36="No"),"Yes","No"))) | G36: =IF(F36="Yes",K11,0) -> 0
A37: Sarah | F37: =IF(B37="","",IF(OR(D37="",E37=""),"Pending",IF(AND(D37>=3,E37="No"),"Yes","No"))) | G37: =IF(F37="Yes",K11,0) -> 0
A38: Sarah | F38: =IF(B38="","",IF(OR(D38="",E38=""),"Pending",IF(AND(D38>=3,E38="No"),"Yes","No"))) | G38: =IF(F38="Yes",K11,0) -> 0
A39: Sarah | F39: =IF(B39="","",IF(OR(D39="",E39=""),"Pending",IF(AND(D39>=3,E39="No"),"Yes","No"))) | G39: =IF(F39="Yes",K11,0) -> 0
A40: Sarah | F40: =IF(B40="","",IF(OR(D40="",E40=""),"Pending",IF(AND(D40>=3,E40="No"),"Yes","No"))) | G40: =IF(F40="Yes",K11,0) -> 0
A41: Sarah | F41: =IF(B41="","",IF(OR(D41="",E41=""),"Pending",IF(AND(D41>=3,E41="No"),"Yes","No"))) | G41: =IF(F41="Yes",K11,0) -> 0
...

Sheet Tech 2.2.6 QC
A1: 2026 OGA Contractor Tech 2.2.6 QC | Site: QC | Tech HC: 20
J2: Milestone Schedule (input)
A3: Legend: | B3: Yellow = fill in per employee (Employee ID, Name, Scorecard Rating, With Active CAP?) | J3: NEO / Start Date | K3: 46276
J4: Tranche 1 Date (PST+OJT Complete) | K4: 46325
A5: TRANCHE 1 — Upon Passing PST + OJT | J5: Tranche 2 Date (+1 month) | K5: =EDATE(K4,1) -> 46356
A6: Supervisor | B6: Employee ID | C6: Name | D6: Scorecard Rating | E6: With Active CAP? | F6: Eligibility (Yes/No) | G6: Amount (PHP) | J6: Tranche 3 Date (Contract End) | K6: 46423
A7: Sarah | F7: =IF(B7="","",IF(E7="","Pending",IF(E7="No","Yes","No"))) | G7: =IF(F7="Yes",K10,0) -> 0
A8: Sarah | F8: =IF(B8="","",IF(E8="","Pending",IF(E8="No","Yes","No"))) | G8: =IF(F8="Yes",K10,0) -> 0 | J8: Rate per Month (PHP) | K8: 2500
A9: Sarah | F9: =IF(B9="","",IF(E9="","Pending",IF(E9="No","Yes","No"))) | G9: =IF(F9="Yes",K10,0) -> 0
A10: Sarah | F10: =IF(B10="","",IF(E10="","Pending",IF(E10="No","Yes","No"))) | G10: =IF(F10="Yes",K10,0) -> 0 | J10: Tranche 1 Amount/Employee | K10: =ROUND((K4-K3)/30*$K$8,2) -> 4083.33
A11: Sarah | F11: =IF(B11="","",IF(E11="","Pending",IF(E11="No","Yes","No"))) | G11: =IF(F11="Yes",K10,0) -> 0 | J11: Tranche 2 Amount/Employee | K11: =ROUND((K5-K4)/30*$K$8,2) -> 2583.33
A12: Sarah | F12: =IF(B12="","",IF(E12="","Pending",IF(E12="No","Yes","No"))) | G12: =IF(F12="Yes",K10,0) -> 0 | J12: Tranche 3 Amount/Employee | K12: =ROUND(MAX(0,(K6-K5))/30*$K$8,2) -> 5583.33
A13: Sarah | F13: =IF(B13="","",IF(E13="","Pending",IF(E13="No","Yes","No"))) | G13: =IF(F13="Yes",K10,0) -> 0 | J13: Total Potential/Employee | K13: =SUM(K10:K12) -> 12249.99
A14: Sarah | F14: =IF(B14="","",IF(E14="","Pending",IF(E14="No","Yes","No"))) | G14: =IF(F14="Yes",K10,0) -> 0
A15: Sarah | F15: =IF(B15="","",IF(E15="","Pending",IF(E15="No","Yes","No"))) | G15: =IF(F15="Yes",K10,0) -> 0 | J15: Tech HC (from Gantt, excludes Support HC) | K15: 20
A16: Sarah | F16: =IF(B16="","",IF(E16="","Pending",IF(E16="No","Yes","No"))) | G16: =IF(F16="Yes",K10,0) -> 0
A17: Sarah | F17: =IF(B17="","",IF(E17="","Pending",IF(E17="No","Yes","No"))) | G17: =IF(F17="Yes",K10,0) -> 0 | J17: Note: Tranche 1 amount = elapsed months from NEO to PST+OJT completion x PHP2,500.
A18: Sarah | F18: =IF(B18="","",IF(E18="","Pending",IF(E18="No","Yes","No"))) | G18: =IF(F18="Yes",K10,0) -> 0 | J18: Tranche 2 = 1 month later. Tranche 3 = elapsed months from Tranche 2 to Contract End (prorated).
A19: Sarah | F19: =IF(B19="","",IF(E19="","Pending",IF(E19="No","Yes","No"))) | G19: =IF(F19="Yes",K10,0) -> 0 | J19: Tranche 1 eligibility = no active CAP (per contract, no scorecard gate).
A20: Sarah | F20: =IF(B20="","",IF(E20="","Pending",IF(E20="No","Yes","No"))) | G20: =IF(F20="Yes",K10,0) -> 0 | J20: Tranche 2 & 3 eligibility = Scorecard >=3.0 AND no active CAP.
A21: Sarah | F21: =IF(B21="","",IF(E21="","Pending",IF(E21="No","Yes","No"))) | G21: =IF(F21="Yes",K10,0) -> 0
A22: Sarah | F22: =IF(B22="","",IF(E22="","Pending",IF(E22="No","Yes","No"))) | G22: =IF(F22="Yes",K10,0) -> 0
A23: Sarah | F23: =IF(B23="","",IF(E23="","Pending",IF(E23="No","Yes","No"))) | G23: =IF(F23="Yes",K10,0) -> 0
A24: Sarah | F24: =IF(B24="","",IF(E24="","Pending",IF(E24="No","Yes","No"))) | G24: =IF(F24="Yes",K10,0) -> 0
A25: Sarah | F25: =IF(B25="","",IF(E25="","Pending",IF(E25="No","Yes","No"))) | G25: =IF(F25="Yes",K10,0) -> 0
A26: Sarah | F26: =IF(B26="","",IF(E26="","Pending",IF(E26="No","Yes","No"))) | G26: =IF(F26="Yes",K10,0) -> 0
A27: Subtotal | G27: =SUM(G7:G26) -> 0
A29: TRANCHE 2 — 1 Month After Tranche 1 (Scorecard-gated)
A30: Supervisor | B30: Employee ID | C30: Name | D30: Scorecard Rating | E30: With Active CAP? | F30: Eligibility (Yes/No) | G30: Amount (PHP)
A31: Sarah | F31: =IF(B31="","",IF(OR(D31="",E31=""),"Pending",IF(AND(D31>=3,E31="No"),"Yes","No"))) | G31: =IF(F31="Yes",K11,0) -> 0
A32: Sarah | F32: =IF(B32="","",IF(OR(D32="",E32=""),"Pending",IF(AND(D32>=3,E32="No"),"Yes","No"))) | G32: =IF(F32="Yes",K11,0) -> 0
A33: Sarah | F33: =IF(B33="","",IF(OR(D33="",E33=""),"Pending",IF(AND(D33>=3,E33="No"),"Yes","No"))) | G33: =IF(F33="Yes",K11,0) -> 0
A34: Sarah | F34: =IF(B34="","",IF(OR(D34="",E34=""),"Pending",IF(AND(D34>=3,E34="No"),"Yes","No"))) | G34: =IF(F34="Yes",K11,0) -> 0
A35: Sarah | F35: =IF(B35="","",IF(OR(D35="",E35=""),"Pending",IF(AND(D35>=3,E35="No"),"Yes","No"))) | G35: =IF(F35="Yes",K11,0) -> 0
A36: Sarah | F36: =IF(B36="","",IF(OR(D36="",E36=""),"Pending",IF(AND(D36>=3,E36="No"),"Yes","No"))) | G36: =IF(F36="Yes",K11,0) -> 0
A37: Sarah | F37: =IF(B37="","",IF(OR(D37="",E37=""),"Pending",IF(AND(D37>=3,E37="No"),"Yes","No"))) | G37: =IF(F37="Yes",K11,0) -> 0
A38: Sarah | F38: =IF(B38="","",IF(OR(D38="",E38=""),"Pending",IF(AND(D38>=3,E38="No"),"Yes","No"))) | G38: =IF(F38="Yes",K11,0) -> 0
A39: Sarah | F39: =IF(B39="","",IF(OR(D39="",E39=""),"Pending",IF(AND(D39>=3,E39="No"),"Yes","No"))) | G39: =IF(F39="Yes",K11,0) -> 0
A40: Sarah | F40: =IF(B40="","",IF(OR(D40="",E40=""),"Pending",IF(AND(D40>=3,E40="No"),"Yes","No"))) | G40: =IF(F40="Yes",K11,0) -> 0
A41: Sarah | F41: =IF(B41="","",IF(OR(D41="",E41=""),"Pending",IF(AND(D41>=3,E41="No"),"Yes","No"))) | G41: =IF(F41="Yes",K11,0) -> 0
...

Sheet Tech 2.2.7 QC
A1: 2026 OGA Contractor Tech 2.2.7 QC | Site: QC | Tech HC: 20
J2: Milestone Schedule (input)
A3: Legend: | B3: Yellow = fill in per employee (Employee ID, Name, Scorecard Rating, With Active CAP?) | J3: NEO / Start Date | K3: 46276
J4: Tranche 1 Date (PST+OJT Complete) | K4: 46325
A5: TRANCHE 1 — Upon Passing PST + OJT | J5: Tranche 2 Date (+1 month) | K5: =EDATE(K4,1) -> 46356
A6: Supervisor | B6: Employee ID | C6: Name | D6: Scorecard Rating | E6: With Active CAP? | F6: Eligibility (Yes/No) | G6: Amount (PHP) | J6: Tranche 3 Date (Contract End) | K6: 46423
A7: Sarah | F7: =IF(B7="","",IF(E7="","Pending",IF(E7="No","Yes","No"))) | G7: =IF(F7="Yes",K10,0) -> 0
A8: Sarah | F8: =IF(B8="","",IF(E8="","Pending",IF(E8="No","Yes","No"))) | G8: =IF(F8="Yes",K10,0) -> 0 | J8: Rate per Month (PHP) | K8: 2500
A9: Sarah | F9: =IF(B9="","",IF(E9="","Pending",IF(E9="No","Yes","No"))) | G9: =IF(F9="Yes",K10,0) -> 0
A10: Sarah | F10: =IF(B10="","",IF(E10="","Pending",IF(E10="No","Yes","No"))) | G10: =IF(F10="Yes",K10,0) -> 0 | J10: Tranche 1 Amount/Employee | K10: =ROUND((K4-K3)/30*$K$8,2) -> 4083.33
A11: Sarah | F11: =IF(B11="","",IF(E11="","Pending",IF(E11="No","Yes","No"))) | G11: =IF(F11="Yes",K10,0) -> 0 | J11: Tranche 2 Amount/Employee | K11: =ROUND((K5-K4)/30*$K$8,2) -> 2583.33
A12: Sarah | F12: =IF(B12="","",IF(E12="","Pending",IF(E12="No","Yes","No"))) | G12: =IF(F12="Yes",K10,0) -> 0 | J12: Tranche 3 Amount/Employee | K12: =ROUND(MAX(0,(K6-K5))/30*$K$8,2) -> 5583.33
A13: Sarah | F13: =IF(B13="","",IF(E13="","Pending",IF(E13="No","Yes","No"))) | G13: =IF(F13="Yes",K10,0) -> 0 | J13: Total Potential/Employee | K13: =SUM(K10:K12) -> 12249.99
A14: Sarah | F14: =IF(B14="","",IF(E14="","Pending",IF(E14="No","Yes","No"))) | G14: =IF(F14="Yes",K10,0) -> 0
A15: Sarah | F15: =IF(B15="","",IF(E15="","Pending",IF(E15="No","Yes","No"))) | G15: =IF(F15="Yes",K10,0) -> 0 | J15: Tech HC (from Gantt, excludes Support HC) | K15: 20
A16: Sarah | F16: =IF(B16="","",IF(E16="","Pending",IF(E16="No","Yes","No"))) | G16: =IF(F16="Yes",K10,0) -> 0
A17: Sarah | F17: =IF(B17="","",IF(E17="","Pending",IF(E17="No","Yes","No"))) | G17: =IF(F17="Yes",K10,0) -> 0 | J17: Note: Tranche 1 amount = elapsed months from NEO to PST+OJT completion x PHP2,500.
A18: Sarah | F18: =IF(B18="","",IF(E18="","Pending",IF(E18="No","Yes","No"))) | G18: =IF(F18="Yes",K10,0) -> 0 | J18: Tranche 2 = 1 month later. Tranche 3 = elapsed months from Tranche 2 to Contract End (prorated).
A19: Sarah | F19: =IF(B19="","",IF(E19="","Pending",IF(E19="No","Yes","No"))) | G19: =IF(F19="Yes",K10,0) -> 0 | J19: Tranche 1 eligibility = no active CAP (per contract, no scorecard gate).
A20: Sarah | F20: =IF(B20="","",IF(E20="","Pending",IF(E20="No","Yes","No"))) | G20: =IF(F20="Yes",K10,0) -> 0 | J20: Tranche 2 & 3 eligibility = Scorecard >=3.0 AND no active CAP.
A21: Sarah | F21: =IF(B21="","",IF(E21="","Pending",IF(E21="No","Yes","No"))) | G21: =IF(F21="Yes",K10,0) -> 0
A22: Sarah | F22: =IF(B22="","",IF(E22="","Pending",IF(E22="No","Yes","No"))) | G22: =IF(F22="Yes",K10,0) -> 0
A23: Sarah | F23: =IF(B23="","",IF(E23="","Pending",IF(E23="No","Yes","No"))) | G23: =IF(F23="Yes",K10,0) -> 0
A24: Sarah | F24: =IF(B24="","",IF(E24="","Pending",IF(E24="No","Yes","No"))) | G24: =IF(F24="Yes",K10,0) -> 0
A25: Sarah | F25: =IF(B25="","",IF(E25="","Pending",IF(E25="No","Yes","No"))) | G25: =IF(F25="Yes",K10,0) -> 0
A26: Sarah | F26: =IF(B26="","",IF(E26="","Pending",IF(E26="No","Yes","No"))) | G26: =IF(F26="Yes",K10,0) -> 0
A27: Subtotal | G27: =SUM(G7:G26) -> 0
A29: TRANCHE 2 — 1 Month After Tranche 1 (Scorecard-gated)
A30: Supervisor | B30: Employee ID | C30: Name | D30: Scorecard Rating | E30: With Active CAP? | F30: Eligibility (Yes/No) | G30: Amount (PHP)
A31: Sarah | F31: =IF(B31="","",IF(OR(D31="",E31=""),"Pending",IF(AND(D31>=3,E31="No"),"Yes","No"))) | G31: =IF(F31="Yes",K11,0) -> 0
A32: Sarah | F32: =IF(B32="","",IF(OR(D32="",E32=""),"Pending",IF(AND(D32>=3,E32="No"),"Yes","No"))) | G32: =IF(F32="Yes",K11,0) -> 0
A33: Sarah | F33: =IF(B33="","",IF(OR(D33="",E33=""),"Pending",IF(AND(D33>=3,E33="No"),"Yes","No"))) | G33: =IF(F33="Yes",K11,0) -> 0
A34: Sarah | F34: =IF(B34="","",IF(OR(D34="",E34=""),"Pending",IF(AND(D34>=3,E34="No"),"Yes","No"))) | G34: =IF(F34="Yes",K11,0) -> 0
A35: Sarah | F35: =IF(B35="","",IF(OR(D35="",E35=""),"Pending",IF(AND(D35>=3,E35="No"),"Yes","No"))) | G35: =IF(F35="Yes",K11,0) -> 0
A36: Sarah | F36: =IF(B36="","",IF(OR(D36="",E36=""),"Pending",IF(AND(D36>=3,E36="No"),"Yes","No"))) | G36: =IF(F36="Yes",K11,0) -> 0
A37: Sarah | F37: =IF(B37="","",IF(OR(D37="",E37=""),"Pending",IF(AND(D37>=3,E37="No"),"Yes","No"))) | G37: =IF(F37="Yes",K11,0) -> 0
A38: Sarah | F38: =IF(B38="","",IF(OR(D38="",E38=""),"Pending",IF(AND(D38>=3,E38="No"),"Yes","No"))) | G38: =IF(F38="Yes",K11,0) -> 0
A39: Sarah | F39: =IF(B39="","",IF(OR(D39="",E39=""),"Pending",IF(AND(D39>=3,E39="No"),"Yes","No"))) | G39: =IF(F39="Yes",K11,0) -> 0
A40: Sarah | F40: =IF(B40="","",IF(OR(D40="",E40=""),"Pending",IF(AND(D40>=3,E40="No"),"Yes","No"))) | G40: =IF(F40="Yes",K11,0) -> 0
A41: Sarah | F41: =IF(B41="","",IF(OR(D41="",E41=""),"Pending",IF(AND(D41>=3,E41="No"),"Yes","No"))) | G41: =IF(F41="Yes",K11,0) -> 0
...

Sheet Tech 2.2.8 DVO
A1: 2026 OGA Contractor Tech 2.2.8 DVO | Site: DVO | Tech HC: 20
J2: Milestone Schedule (input)
A3: Legend: | B3: Yellow = fill in per employee (Employee ID, Name, Scorecard Rating, With Active CAP?) | J3: NEO / Start Date | K3: 46283
J4: Tranche 1 Date (PST+OJT Complete) | K4: 46332
A5: TRANCHE 1 — Upon Passing PST + OJT | J5: Tranche 2 Date (+1 month) | K5: =EDATE(K4,1) -> 46362
A6: Supervisor | B6: Employee ID | C6: Name | D6: Scorecard Rating | E6: With Active CAP? | F6: Eligibility (Yes/No) | G6: Amount (PHP) | J6: Tranche 3 Date (Contract End) | K6: 46430
A7: Sarah | F7: =IF(B7="","",IF(E7="","Pending",IF(E7="No","Yes","No"))) | G7: =IF(F7="Yes",K10,0) -> 0
A8: Sarah | F8: =IF(B8="","",IF(E8="","Pending",IF(E8="No","Yes","No"))) | G8: =IF(F8="Yes",K10,0) -> 0 | J8: Rate per Month (PHP) | K8: 2500
A9: Sarah | F9: =IF(B9="","",IF(E9="","Pending",IF(E9="No","Yes","No"))) | G9: =IF(F9="Yes",K10,0) -> 0
A10: Sarah | F10: =IF(B10="","",IF(E10="","Pending",IF(E10="No","Yes","No"))) | G10: =IF(F10="Yes",K10,0) -> 0 | J10: Tranche 1 Amount/Employee | K10: =ROUND((K4-K3)/30*$K$8,2) -> 4083.33
A11: Sarah | F11: =IF(B11="","",IF(E11="","Pending",IF(E11="No","Yes","No"))) | G11: =IF(F11="Yes",K10,0) -> 0 | J11: Tranche 2 Amount/Employee | K11: =ROUND((K5-K4)/30*$K$8,2) -> 2500
A12: Sarah | F12: =IF(B12="","",IF(E12="","Pending",IF(E12="No","Yes","No"))) | G12: =IF(F12="Yes",K10,0) -> 0 | J12: Tranche 3 Amount/Employee | K12: =ROUND(MAX(0,(K6-K5))/30*$K$8,2) -> 5666.67
A13: Sarah | F13: =IF(B13="","",IF(E13="","Pending",IF(E13="No","Yes","No"))) | G13: =IF(F13="Yes",K10,0) -> 0 | J13: Total Potential/Employee | K13: =SUM(K10:K12) -> 12250
A14: Sarah | F14: =IF(B14="","",IF(E14="","Pending",IF(E14="No","Yes","No"))) | G14: =IF(F14="Yes",K10,0) -> 0
A15: Sarah | F15: =IF(B15="","",IF(E15="","Pending",IF(E15="No","Yes","No"))) | G15: =IF(F15="Yes",K10,0) -> 0 | J15: Tech HC (from Gantt, excludes Support HC) | K15: 20
A16: Sarah | F16: =IF(B16="","",IF(E16="","Pending",IF(E16="No","Yes","No"))) | G16: =IF(F16="Yes",K10,0) -> 0
A17: Sarah | F17: =IF(B17="","",IF(E17="","Pending",IF(E17="No","Yes","No"))) | G17: =IF(F17="Yes",K10,0) -> 0 | J17: Note: Tranche 1 amount = elapsed months from NEO to PST+OJT completion x PHP2,500.
A18: Sarah | F18: =IF(B18="","",IF(E18="","Pending",IF(E18="No","Yes","No"))) | G18: =IF(F18="Yes",K10,0) -> 0 | J18: Tranche 2 = 1 month later. Tranche 3 = elapsed months from Tranche 2 to Contract End (prorated).
A19: Sarah | F19: =IF(B19="","",IF(E19="","Pending",IF(E19="No","Yes","No"))) | G19: =IF(F19="Yes",K10,0) -> 0 | J19: Tranche 1 eligibility = no active CAP (per contract, no scorecard gate).
A20: Sarah | F20: =IF(B20="","",IF(E20="","Pending",IF(E20="No","Yes","No"))) | G20: =IF(F20="Yes",K10,0) -> 0 | J20: Tranche 2 & 3 eligibility = Scorecard >=3.0 AND no active CAP.
A21: Sarah | F21: =IF(B21="","",IF(E21="","Pending",IF(E21="No","Yes","No"))) | G21: =IF(F21="Yes",K10,0) -> 0
A22: Sarah | F22: =IF(B22="","",IF(E22="","Pending",IF(E22="No","Yes","No"))) | G22: =IF(F22="Yes",K10,0) -> 0
A23: Sarah | F23: =IF(B23="","",IF(E23="","Pending",IF(E23="No","Yes","No"))) | G23: =IF(F23="Yes",K10,0) -> 0
A24: Sarah | F24: =IF(B24="","",IF(E24="","Pending",IF(E24="No","Yes","No"))) | G24: =IF(F24="Yes",K10,0) -> 0
A25: Sarah | F25: =IF(B25="","",IF(E25="","Pending",IF(E25="No","Yes","No"))) | G25: =IF(F25="Yes",K10,0) -> 0
A26: Sarah | F26: =IF(B26="","",IF(E26="","Pending",IF(E26="No","Yes","No"))) | G26: =IF(F26="Yes",K10,0) -> 0
A27: Subtotal | G27: =SUM(G7:G26) -> 0
A29: TRANCHE 2 — 1 Month After Tranche 1 (Scorecard-gated)
A30: Supervisor | B30: Employee ID | C30: Name | D30: Scorecard Rating | E30: With Active CAP? | F30: Eligibility (Yes/No) | G30: Amount (PHP)
A31: Sarah | F31: =IF(B31="","",IF(OR(D31="",E31=""),"Pending",IF(AND(D31>=3,E31="No"),"Yes","No"))) | G31: =IF(F31="Yes",K11,0) -> 0
A32: Sarah | F32: =IF(B32="","",IF(OR(D32="",E32=""),"Pending",IF(AND(D32>=3,E32="No"),"Yes","No"))) | G32: =IF(F32="Yes",K11,0) -> 0
A33: Sarah | F33: =IF(B33="","",IF(OR(D33="",E33=""),"Pending",IF(AND(D33>=3,E33="No"),"Yes","No"))) | G33: =IF(F33="Yes",K11,0) -> 0
A34: Sarah | F34: =IF(B34="","",IF(OR(D34="",E34=""),"Pending",IF(AND(D34>=3,E34="No"),"Yes","No"))) | G34: =IF(F34="Yes",K11,0) -> 0
A35: Sarah | F35: =IF(B35="","",IF(OR(D35="",E35=""),"Pending",IF(AND(D35>=3,E35="No"),"Yes","No"))) | G35: =IF(F35="Yes",K11,0) -> 0
A36: Sarah | F36: =IF(B36="","",IF(OR(D36="",E36=""),"Pending",IF(AND(D36>=3,E36="No"),"Yes","No"))) | G36: =IF(F36="Yes",K11,0) -> 0
A37: Sarah | F37: =IF(B37="","",IF(OR(D37="",E37=""),"Pending",IF(AND(D37>=3,E37="No"),"Yes","No"))) | G37: =IF(F37="Yes",K11,0) -> 0
A38: Sarah | F38: =IF(B38="","",IF(OR(D38="",E38=""),"Pending",IF(AND(D38>=3,E38="No"),"Yes","No"))) | G38: =IF(F38="Yes",K11,0) -> 0
A39: Sarah | F39: =IF(B39="","",IF(OR(D39="",E39=""),"Pending",IF(AND(D39>=3,E39="No"),"Yes","No"))) | G39: =IF(F39="Yes",K11,0) -> 0
A40: Sarah | F40: =IF(B40="","",IF(OR(D40="",E40=""),"Pending",IF(AND(D40>=3,E40="No"),"Yes","No"))) | G40: =IF(F40="Yes",K11,0) -> 0
A41: Sarah | F41: =IF(B41="","",IF(OR(D41="",E41=""),"Pending",IF(AND(D41>=3,E41="No"),"Yes","No"))) | G41: =IF(F41="Yes",K11,0) -> 0
...

Sheet Tech 2.2.9 CEB
A1: 2026 OGA Contractor Tech 2.2.9 CEB | Site: CEB | Tech HC: 15
J2: Milestone Schedule (input)
A3: Legend: | B3: Yellow = fill in per employee (Employee ID, Name, Scorecard Rating, With Active CAP?) | J3: NEO / Start Date | K3: 46283
J4: Tranche 1 Date (PST+OJT Complete) | K4: 46332
A5: TRANCHE 1 — Upon Passing PST + OJT | J5: Tranche 2 Date (+1 month) | K5: =EDATE(K4,1) -> 46362
A6: Supervisor | B6: Employee ID | C6: Name | D6: Scorecard Rating | E6: With Active CAP? | F6: Eligibility (Yes/No) | G6: Amount (PHP) | J6: Tranche 3 Date (Contract End) | K6: 46430
A7: Sarah | F7: =IF(B7="","",IF(E7="","Pending",IF(E7="No","Yes","No"))) | G7: =IF(F7="Yes",K10,0) -> 0
A8: Sarah | F8: =IF(B8="","",IF(E8="","Pending",IF(E8="No","Yes","No"))) | G8: =IF(F8="Yes",K10,0) -> 0 | J8: Rate per Month (PHP) | K8: 2500
A9: Sarah | F9: =IF(B9="","",IF(E9="","Pending",IF(E9="No","Yes","No"))) | G9: =IF(F9="Yes",K10,0) -> 0
A10: Sarah | F10: =IF(B10="","",IF(E10="","Pending",IF(E10="No","Yes","No"))) | G10: =IF(F10="Yes",K10,0) -> 0 | J10: Tranche 1 Amount/Employee | K10: =ROUND((K4-K3)/30*$K$8,2) -> 4083.33
A11: Sarah | F11: =IF(B11="","",IF(E11="","Pending",IF(E11="No","Yes","No"))) | G11: =IF(F11="Yes",K10,0) -> 0 | J11: Tranche 2 Amount/Employee | K11: =ROUND((K5-K4)/30*$K$8,2) -> 2500
A12: Sarah | F12: =IF(B12="","",IF(E12="","Pending",IF(E12="No","Yes","No"))) | G12: =IF(F12="Yes",K10,0) -> 0 | J12: Tranche 3 Amount/Employee | K12: =ROUND(MAX(0,(K6-K5))/30*$K$8,2) -> 5666.67
A13: Sarah | F13: =IF(B13="","",IF(E13="","Pending",IF(E13="No","Yes","No"))) | G13: =IF(F13="Yes",K10,0) -> 0 | J13: Total Potential/Employee | K13: =SUM(K10:K12) -> 12250
A14: Sarah | F14: =IF(B14="","",IF(E14="","Pending",IF(E14="No","Yes","No"))) | G14: =IF(F14="Yes",K10,0) -> 0
A15: Sarah | F15: =IF(B15="","",IF(E15="","Pending",IF(E15="No","Yes","No"))) | G15: =IF(F15="Yes",K10,0) -> 0 | J15: Tech HC (from Gantt, excludes Support HC) | K15: 15
A16: Sarah | F16: =IF(B16="","",IF(E16="","Pending",IF(E16="No","Yes","No"))) | G16: =IF(F16="Yes",K10,0) -> 0
A17: Sarah | F17: =IF(B17="","",IF(E17="","Pending",IF(E17="No","Yes","No"))) | G17: =IF(F17="Yes",K10,0) -> 0 | J17: Note: Tranche 1 amount = elapsed months from NEO to PST+OJT completion x PHP2,500.
A18: Sarah | F18: =IF(B18="","",IF(E18="","Pending",IF(E18="No","Yes","No"))) | G18: =IF(F18="Yes",K10,0) -> 0 | J18: Tranche 2 = 1 month later. Tranche 3 = elapsed months from Tranche 2 to Contract End (prorated).
A19: Sarah | F19: =IF(B19="","",IF(E19="","Pending",IF(E19="No","Yes","No"))) | G19: =IF(F19="Yes",K10,0) -> 0 | J19: Tranche 1 eligibility = no active CAP (per contract, no scorecard gate).
A20: Sarah | F20: =IF(B20="","",IF(E20="","Pending",IF(E20="No","Yes","No"))) | G20: =IF(F20="Yes",K10,0) -> 0 | J20: Tranche 2 & 3 eligibility = Scorecard >=3.0 AND no active CAP.
A21: Sarah | F21: =IF(B21="","",IF(E21="","Pending",IF(E21="No","Yes","No"))) | G21: =IF(F21="Yes",K10,0) -> 0
A22: Subtotal | G22: =SUM(G7:G21) -> 0
A24: TRANCHE 2 — 1 Month After Tranche 1 (Scorecard-gated)
A25: Supervisor | B25: Employee ID | C25: Name | D25: Scorecard Rating | E25: With Active CAP? | F25: Eligibility (Yes/No) | G25: Amount (PHP)
A26: Sarah | F26: =IF(B26="","",IF(OR(D26="",E26=""),"Pending",IF(AND(D26>=3,E26="No"),"Yes","No"))) | G26: =IF(F26="Yes",K11,0) -> 0
A27: Sarah | F27: =IF(B27="","",IF(OR(D27="",E27=""),"Pending",IF(AND(D27>=3,E27="No"),"Yes","No"))) | G27: =IF(F27="Yes",K11,0) -> 0
A28: Sarah | F28: =IF(B28="","",IF(OR(D28="",E28=""),"Pending",IF(AND(D28>=3,E28="No"),"Yes","No"))) | G28: =IF(F28="Yes",K11,0) -> 0
A29: Sarah | F29: =IF(B29="","",IF(OR(D29="",E29=""),"Pending",IF(AND(D29>=3,E29="No"),"Yes","No"))) | G29: =IF(F29="Yes",K11,0) -> 0
A30: Sarah | F30: =IF(B30="","",IF(OR(D30="",E30=""),"Pending",IF(AND(D30>=3,E30="No"),"Yes","No"))) | G30: =IF(F30="Yes",K11,0) -> 0
A31: Sarah | F31: =IF(B31="","",IF(OR(D31="",E31=""),"Pending",IF(AND(D31>=3,E31="No"),"Yes","No"))) | G31: =IF(F31="Yes",K11,0) -> 0
A32: Sarah | F32: =IF(B32="","",IF(OR(D32="",E32=""),"Pending",IF(AND(D32>=3,E32="No"),"Yes","No"))) | G32: =IF(F32="Yes",K11,0) -> 0
A33: Sarah | F33: =IF(B33="","",IF(OR(D33="",E33=""),"Pending",IF(AND(D33>=3,E33="No"),"Yes","No"))) | G33: =IF(F33="Yes",K11,0) -> 0
A34: Sarah | F34: =IF(B34="","",IF(OR(D34="",E34=""),"Pending",IF(AND(D34>=3,E34="No"),"Yes","No"))) | G34: =IF(F34="Yes",K11,0) -> 0
A35: Sarah | F35: =IF(B35="","",IF(OR(D35="",E35=""),"Pending",IF(AND(D35>=3,E35="No"),"Yes","No"))) | G35: =IF(F35="Yes",K11,0) -> 0
A36: Sarah | F36: =IF(B36="","",IF(OR(D36="",E36=""),"Pending",IF(AND(D36>=3,E36="No"),"Yes","No"))) | G36: =IF(F36="Yes",K11,0) -> 0
A37: Sarah | F37: =IF(B37="","",IF(OR(D37="",E37=""),"Pending",IF(AND(D37>=3,E37="No"),"Yes","No"))) | G37: =IF(F37="Yes",K11,0) -> 0
A38: Sarah | F38: =IF(B38="","",IF(OR(D38="",E38=""),"Pending",IF(AND(D38>=3,E38="No"),"Yes","No"))) | G38: =IF(F38="Yes",K11,0) -> 0
A39: Sarah | F39: =IF(B39="","",IF(OR(D39="",E39=""),"Pending",IF(AND(D39>=3,E39="No"),"Yes","No"))) | G39: =IF(F39="Yes",K11,0) -> 0
A40: Sarah | F40: =IF(B40="","",IF(OR(D40="",E40=""),"Pending",IF(AND(D40>=3,E40="No"),"Yes","No"))) | G40: =IF(F40="Yes",K11,0) -> 0
A41: Subtotal | G41: =SUM(G26:G40) -> 0
...

Sheet Tech 2.2.10 DVO
A1: 2026 OGA Contractor Tech 2.2.10 DVO | Site: DVO | Tech HC: 20
J2: Milestone Schedule (input)
A3: Legend: | B3: Yellow = fill in per employee (Employee ID, Name, Scorecard Rating, With Active CAP?) | J3: NEO / Start Date | K3: 46304
J4: Tranche 1 Date (PST+OJT Complete) | K4: 46353
A5: TRANCHE 1 — Upon Passing PST + OJT | J5: Tranche 2 Date (+1 month) | K5: =EDATE(K4,1) -> 46383
A6: Supervisor | B6: Employee ID | C6: Name | D6: Scorecard Rating | E6: With Active CAP? | F6: Eligibility (Yes/No) | G6: Amount (PHP) | J6: Tranche 3 Date (Contract End) | K6: 46423
A7: Sarah | F7: =IF(B7="","",IF(E7="","Pending",IF(E7="No","Yes","No"))) | G7: =IF(F7="Yes",K10,0) -> 0
A8: Sarah | F8: =IF(B8="","",IF(E8="","Pending",IF(E8="No","Yes","No"))) | G8: =IF(F8="Yes",K10,0) -> 0 | J8: Rate per Month (PHP) | K8: 2500
A9: Sarah | F9: =IF(B9="","",IF(E9="","Pending",IF(E9="No","Yes","No"))) | G9: =IF(F9="Yes",K10,0) -> 0
A10: Sarah | F10: =IF(B10="","",IF(E10="","Pending",IF(E10="No","Yes","No"))) | G10: =IF(F10="Yes",K10,0) -> 0 | J10: Tranche 1 Amount/Employee | K10: =ROUND((K4-K3)/30*$K$8,2) -> 4083.33
A11: Sarah | F11: =IF(B11="","",IF(E11="","Pending",IF(E11="No","Yes","No"))) | G11: =IF(F11="Yes",K10,0) -> 0 | J11: Tranche 2 Amount/Employee | K11: =ROUND((K5-K4)/30*$K$8,2) -> 2500
A12: Sarah | F12: =IF(B12="","",IF(E12="","Pending",IF(E12="No","Yes","No"))) | G12: =IF(F12="Yes",K10,0) -> 0 | J12: Tranche 3 Amount/Employee | K12: =ROUND(MAX(0,(K6-K5))/30*$K$8,2) -> 3333.33
A13: Sarah | F13: =IF(B13="","",IF(E13="","Pending",IF(E13="No","Yes","No"))) | G13: =IF(F13="Yes",K10,0) -> 0 | J13: Total Potential/Employee | K13: =SUM(K10:K12) -> 9916.66
A14: Sarah | F14: =IF(B14="","",IF(E14="","Pending",IF(E14="No","Yes","No"))) | G14: =IF(F14="Yes",K10,0) -> 0
A15: Sarah | F15: =IF(B15="","",IF(E15="","Pending",IF(E15="No","Yes","No"))) | G15: =IF(F15="Yes",K10,0) -> 0 | J15: Tech HC (from Gantt, excludes Support HC) | K15: 20
A16: Sarah | F16: =IF(B16="","",IF(E16="","Pending",IF(E16="No","Yes","No"))) | G16: =IF(F16="Yes",K10,0) -> 0
A17: Sarah | F17: =IF(B17="","",IF(E17="","Pending",IF(E17="No","Yes","No"))) | G17: =IF(F17="Yes",K10,0) -> 0 | J17: Note: Tranche 1 amount = elapsed months from NEO to PST+OJT completion x PHP2,500.
A18: Sarah | F18: =IF(B18="","",IF(E18="","Pending",IF(E18="No","Yes","No"))) | G18: =IF(F18="Yes",K10,0) -> 0 | J18: Tranche 2 = 1 month later. Tranche 3 = elapsed months from Tranche 2 to Contract End (prorated).
A19: Sarah | F19: =IF(B19="","",IF(E19="","Pending",IF(E19="No","Yes","No"))) | G19: =IF(F19="Yes",K10,0) -> 0 | J19: Tranche 1 eligibility = no active CAP (per contract, no scorecard gate).
A20: Sarah | F20: =IF(B20="","",IF(E20="","Pending",IF(E20="No","Yes","No"))) | G20: =IF(F20="Yes",K10,0) -> 0 | J20: Tranche 2 & 3 eligibility = Scorecard >=3.0 AND no active CAP.
A21: Sarah | F21: =IF(B21="","",IF(E21="","Pending",IF(E21="No","Yes","No"))) | G21: =IF(F21="Yes",K10,0) -> 0
A22: Sarah | F22: =IF(B22="","",IF(E22="","Pending",IF(E22="No","Yes","No"))) | G22: =IF(F22="Yes",K10,0) -> 0
A23: Sarah | F23: =IF(B23="","",IF(E23="","Pending",IF(E23="No","Yes","No"))) | G23: =IF(F23="Yes",K10,0) -> 0
A24: Sarah | F24: =IF(B24="","",IF(E24="","Pending",IF(E24="No","Yes","No"))) | G24: =IF(F24="Yes",K10,0) -> 0
A25: Sarah | F25: =IF(B25="","",IF(E25="","Pending",IF(E25="No","Yes","No"))) | G25: =IF(F25="Yes",K10,0) -> 0
A26: Sarah | F26: =IF(B26="","",IF(E26="","Pending",IF(E26="No","Yes","No"))) | G26: =IF(F26="Yes",K10,0) -> 0
A27: Subtotal | G27: =SUM(G7:G26) -> 0
A29: TRANCHE 2 — 1 Month After Tranche 1 (Scorecard-gated)
A30: Supervisor | B30: Employee ID | C30: Name | D30: Scorecard Rating | E30: With Active CAP? | F30: Eligibility (Yes/No) | G30: Amount (PHP)
A31: Sarah | F31: =IF(B31="","",IF(OR(D31="",E31=""),"Pending",IF(AND(D31>=3,E31="No"),"Yes","No"))) | G31: =IF(F31="Yes",K11,0) -> 0
A32: Sarah | F32: =IF(B32="","",IF(OR(D32="",E32=""),"Pending",IF(AND(D32>=3,E32="No"),"Yes","No"))) | G32: =IF(F32="Yes",K11,0) -> 0
A33: Sarah | F33: =IF(B33="","",IF(OR(D33="",E33=""),"Pending",IF(AND(D33>=3,E33="No"),"Yes","No"))) | G33: =IF(F33="Yes",K11,0) -> 0
A34: Sarah | F34: =IF(B34="","",IF(OR(D34="",E34=""),"Pending",IF(AND(D34>=3,E34="No"),"Yes","No"))) | G34: =IF(F34="Yes",K11,0) -> 0
A35: Sarah | F35: =IF(B35="","",IF(OR(D35="",E35=""),"Pending",IF(AND(D35>=3,E35="No"),"Yes","No"))) | G35: =IF(F35="Yes",K11,0) -> 0
A36: Sarah | F36: =IF(B36="","",IF(OR(D36="",E36=""),"Pending",IF(AND(D36>=3,E36="No"),"Yes","No"))) | G36: =IF(F36="Yes",K11,0) -> 0
A37: Sarah | F37: =IF(B37="","",IF(OR(D37="",E37=""),"Pending",IF(AND(D37>=3,E37="No"),"Yes","No"))) | G37: =IF(F37="Yes",K11,0) -> 0
A38: Sarah | F38: =IF(B38="","",IF(OR(D38="",E38=""),"Pending",IF(AND(D38>=3,E38="No"),"Yes","No"))) | G38: =IF(F38="Yes",K11,0) -> 0
A39: Sarah | F39: =IF(B39="","",IF(OR(D39="",E39=""),"Pending",IF(AND(D39>=3,E39="No"),"Yes","No"))) | G39: =IF(F39="Yes",K11,0) -> 0
A40: Sarah | F40: =IF(B40="","",IF(OR(D40="",E40=""),"Pending",IF(AND(D40>=3,E40="No"),"Yes","No"))) | G40: =IF(F40="Yes",K11,0) -> 0
A41: Sarah | F41: =IF(B41="","",IF(OR(D41="",E41=""),"Pending",IF(AND(D41>=3,E41="No"),"Yes","No"))) | G41: =IF(F41="Yes",K11,0) -> 0
...

Sheet Tech 2.2.11 QC
A1: 2026 OGA Contractor Tech 2.2.11 QC | Site: QC | Tech HC: 20
J2: Milestone Schedule (input)
A3: Legend: | B3: Yellow = fill in per employee (Employee ID, Name, Scorecard Rating, With Active CAP?) | J3: NEO / Start Date | K3: 46290
J4: Tranche 1 Date (PST+OJT Complete) | K4: 46339
A5: TRANCHE 1 — Upon Passing PST + OJT | J5: Tranche 2 Date (+1 month) | K5: =EDATE(K4,1) -> 46369
